			try { return this->at(n); } catch (const std::exception& e) {
